Workbook

Sheet 현자산
G1: 2025. 12월 기준
B2: 25년10월 | E2: 순자산 | F2: 총자산 | G2: 대출/손실
E3: =SUM(F3:G3) -> 1049718000 | F3: =SUM(E6,F9,F14,G19) -> 1194418000 | G3: =SUM(G9,G14,H19) -> -144700000
B5: 아파트 | E5: 순자산 | F5: 현시세 | G5: 대출
E6: =F6+G6 -> 700000000 | F6: 700000000 | G6: 0
B8: 상가 | E8: 순자산 | F8: 현시세 | G8: 대출
E9: =F9+G9 -> 106800000 | F9: 250000000 | G9: =SUM(G10:G11) -> -143200000
F10: 국민은행 | G10: -113200000
F11: 지수 | G11: -30000000
B13: 케이씨글로벌 | E13: 순자산 | F13: 투자금 | G13: 손실 | H13: 26.1.7일로 투자정리 & 주식재투자 (대출937만+경희계좌1,000만)
E14: =F14+G14 -> 18500000 | F14: =20000000+50000000-50000000 -> 20000000 | G14: -1500000 | H14: 150만 주식투자: 손실중 / 25.12.18일 5,500만 경희입금
E15: 보험대출 투자 5,000만원은 상환완료 | H15: 소액추가 100만원 포함/손실에서 Minus
B17: 26.3월 기준 : 만기납입액 / 실손제외(실손보험료 만기환급은 확인필요)
B18: 보험 납입액 | E18: 2056년 에상 | F18: 사망보험금 | G18: 만기납입액 | H18: 대출액 | I18: 해지환급금(26.3) | K18: 대출가능/이자율
E19: =SUM(E20:E25) -> 293400000 | F19: =SUM(F20:F25) -> 274630000 | G19: =SUM(G20:G25) -> 224418000 | H19: =SUM(H20:H24) -> 0 | I19: =SUM(I20:I24) -> 168700000 | J19: =(I20*J20+I21*J21+I22*J22+I23*J23+I24*J24+I25*J25)/I19 -> 0.87580173 | K19: =SUM(K20:K24) -> 137320000 | L19: =(K20*L20+K21*L21+K22*L22+K23*L23+K24*L24)/K19 -> 0.052383193
C20: 갑철 리빙케어 | E20: =ROUND(F20+G20*0.1,-5) -> 116300000 | F20: =ROUND(G20*1.1,-4) -> 106630000 | G20: 96936000 | I20: 75500000 | J20: =I20/G20 -> 0.77886441 | K20: 64770000 | L20: 0.055 | M20: 23.6월 납입완료, 80세까지 사고사망시 4억원
C21: 갑철 유니버셜 | E21: =ROUND(F21+G21*0.05,-5) -> 31100000 | F21: 30000000 | G21: =ROUND(95100*240,-3) -> 22824000 | I21: 13300000 | J21: =I21/G21 -> 0.58271994 | K21: 9210000 | L21: 0.04 | M21: 30.9월 납입만기/유지필요
C22: 경희 리빙케어 | E22: =ROUND(F22+G22*0.1,-5) -> 80100000 | F22: 75000000 | G22: 51200000 | I22: 46800000 | J22: =I22/G22 -> 0.9140625 | K22: 40940000 | L22: 0.0525 | M22: 20.8월 납입완료
C23: 경희 유니버셜 | E23: =ROUND(F23+G23*0.08,-5) -> 52900000 | F23: 50000000 | G23: =304150*120 -> 36498000 | I23: 28900000 | J23: =I23/G23 -> 0.79182421 | K23: 19050000 | L23: 0.0412 | M23: 26.2월 납입만기/유지필요
C24: 경희 여성시대 | E24: 만기환급무 | F24: 만기환급무 | G24: 3960000 | I24: 4200000 | J24: =I24/G24 -> 1.0606061 | K24: 3350000 | L24: 0.098 | M24: 납입완료/41.6월 만기/유지필요
C25: 경희 우체국 | E25: 13000000 | F25: 13000000 | G25: =ROUND(54000*240,-6) -> 13000000 | I25: =ROUND(54000*231,-6) -> 12000000 | J25: =I25/G25 -> 0.92307692 | M25: 26.6월 납입만기/41.7월까지 보장
E26: =E19/F19 -> 1.0683465 | F26: 1 | M26: - 26.7월 만기배당금 44만원수령 : 렌지후드교체(44만원)
M27: - 일반사망보험금 : 2,000만원, 재해/질병 4,000-6,000만원
M28: * 80세 보장만기시에는 환급금이 있는지???
C29: 별도> 운전자보험(20년) : 무배당 사멍화재 운전자보험 안전운전 파트너 플러스(2404.6) 1종(연만기/납입면제형)
D30: 2024. 8. 9 - 2044. 8. 8일 (매년 9월 갱신, 83세까지 운전)
D31: 상해사망 / 상해 후유장애(3-100%) | G31: 5000 | J31: 별도> KB손해보험 : 다이렉트주택화재보험 - 5년만기(2026.7.22-2031.7.22)
D32: 자동차사고 부상치료지원금 2 | G32: 3000 | J32: 건물 | K32: 화재손해(실손보상) | O32: 30000
D33: 교통사고 처리지원금7(중상해보장확대) | G33: 7000 | K33: 붕괴침강및사태로인한 재산손해(실손보상) | O33: 30000
D34: 교통사고 처리지원금7(부상) | G34: 2000 | K34: 건물복구비용지원(화 재) | O34: 6000
D35: 교통사고 처리지원금7(부상) | G35: 2000 | K35: 스프링클러누출손해 (실손보상) | O35: 30000
D36: 교통사고 처리지원금(6주미만부상,주대법규위반)3 | G36: 1000 | J36: 가재 | K36: 화재손해(실손보상) | O36: 10000
D37: 운전자 벌금 (대인) | G37: 3000 | J37: 도구 | K37: 도난손해(주택비명기) | O37: 1000
D38: 운전자 벌금 (대물) | G38: 500 | K38: 붕괴침강및사태로인한 재산손해(실손보상 | O38: 10000
D39: 자동차운전중 보복운전 피해위로금 | G39: 30 | K39: 스프링클러누출손해 (실손보상) | O39: 10000
D40: 자동차사고 변호사선임비용7(경찰조사포함) | G40: 5000 | J40: 재물 | K40: 화재배상책임 | O40: 대인 1,5억원 | P40: 사고당 무한
D41: 자동차사고 민사소송 법률비용손해 | G41: 2000 | J41: 기타 | O41: 대물 20억원
D42: 가족 일상생활중 배상책임2 | G42: 10000 | K42: 주택임시거주비(1-90일, 화재/침강/사태/붕괴/급배수누출) | O42: 일25만원
D43: (공제)가족 일상생활중 배상책임2 | G43: 50 | K43: 층간소음피해보장 | O43: 100
D44: 예상만기환급금(2044.8월) | G44: 1003275 | K44: 급배수시설누출손해 (자기부담금10%)(주 택) | O44: 500
...

Sheet 기초연금
B2: 기초연금 제도변경에 따른 수급예상 | D2: ※ 9/1일 신규발표 : 노인소득하위70% 유지, 45-70%는 27년 부부감액 20% 유지(28년부터는???)
B5: 26년 7월 기준 소득인정액 | C5: 3520000 | D5: (상가월세 30만원 추가후)
B7: 2026년 기준 중위소득 | C7: 4199292
B8: 2026년 노인소득하위 70% | C8: 3952000 | D8: =C8/C7 -> 0.94111103
B10: 6년 8월 개정안 관련 뉴스 | C10: 27년부터 기준 중위소득의 90%로 감소 | F10: <주택연금 누적수령액> | G10: 소득감소 | H10: 주택연금 고려후
F11: 3월기준/대출로 계산 | G11: 0.04 | H11: 예상인정액 | I11: 부족금액 | J11: 해당여부
B12: 2026년 (소득하위70%) | C12: =C8 -> 3952000 | D12: =C$5-C12 -> -432000 | E12: 수급중 | F12: =2203450*12 -> 26441400 | H12: =C5 -> 3520000 | I12: =H12-C12 -> -432000 | J12: 해당
B13: 2027년 (90.0%) | C13: =C$7*0.9 -> 3779362.8 | D13: =C$5-C13 -> -259362.8 | E13: 해당 | F13: =F12+(2203450*12) -> 52882800 | G13: =F12*G$11/12 -> 88138 | H13: =C$5-G13 -> 3431862 | I13: =H13-C13 -> -347500.8 | J13: 해당
B14: 2028년 (86.6%) | C14: =C$7*0.866 -> 3636586.9 | D14: =C$5-C14 -> -116586.87 | E14: 해당 | F14: =F13+(2203450*12) -> 79324200 | G14: =F13*G$11/12 -> 176276 | H14: =C$5-G14 -> 3343724 | I14: =H14-C14 -> -292862.87 | J14: 해당
B15: 2029년 (83.3%) | C15: =C$7*0.833 -> 3498010.2 | D15: =C$5-C15 -> 21989.764 | E15: 미해당 | F15: =F14+(2203450*12) -> 105765600 | G15: =F14*G$11/12 -> 264414 | H15: =C$5-G15 -> 3255586 | I15: =H15-C15 -> -242424.24 | J15: 해당
B16: 2030년 (80.0%) | C16: =C$7*0.8 -> 3359433.6 | D16: =C$5-C16 -> 160566.4 | E16: 미해당 | F16: =F15+(2203450*12) -> 132207000 | G16: =F15*G$11/12 -> 352552 | H16: =C$5-G16 -> 3167448 | I16: =H16-C16 -> -191985.6 | J16: 해당
B18: # 상가 매도후에는 현금자산을 감소시켜야 함 (기본공제후 이자4%를 소득으로 인정) | J18: # 주택연금 수령(대출)으로 계속 해당이 예상됨
B19: - 지수원금 4천만원 상환 (이자포함) | J19: - 아파트/상가의 공시가격 변동은 변수
B20: - 손녀 5천만원까지 상속 (서연 4천만원 추가, 지수애기는 5천만원 증여가능) | J20: - 부부가구 감액 폐지는 ??? / 폐지되면 수급액 증가
B21: : 지수애기 안되면, 차량 사주기 (증여가 안되는 방법은?)
B22: - 딸들 생활비 현금보조로 금융자산 감소/조정 필요 : 조기상속으로 진행

Sheet 관리비
B2: 국민카드 이용내역 : 관리비 / 통신비 / 코웨이 | M2: =M5-M3 -> -49400 | O2: 26년7월 기준 잉여금 | P2: =P3-S3 -> 478000
B3: 2025.04-26.03 | L3: 계산 가정 | M3: 650000 | O3: 사용가능 금액 | P3: =P4+S4 -> 1978000 | R3: 사용예상금액 | S3: 1500000
B4: 월별 | C4: 평균 | D4: 관리비 | E4: 코웨이-1 | F4: 코웨이-2 | G4: 코웨이-3 | H4: 코웨이-4 | I4: SK-1 | J4: SK-2 | K4: 코웨이 | L4: 통신비 | M4: 통신비외 | O4: 잔액/사용가능 | P4: =P5-P10 -> 1438000 | R4: 잔액/사용가능 | S4: =S5-S10 -> 540000
B5: 월평균 | C5: =ROUND(SUM(D5:J5),-3) -> 698000 | D5: =ROUND(AVERAGE(D6:D17),-2) -> 536400 | E5: =ROUND(AVERAGE(E6:E17),-2) -> 31700 | F5: =ROUND(AVERAGE(F6:F17),-2) -> 28600 | G5: =ROUND(AVERAGE(G6:G17),-2) -> 3900 | I5: =ROUND(AVERAGE(I6:I17),-2) -> 52600 | J5: =ROUND(AVERAGE(J6:J17),-2) -> 44400 | K5: =ROUND(AVERAGE(K6:K17),-2) -> 64200 | L5: =ROUND(AVERAGE(L6:L17),-2) -> 97000 | M5: =ROUND(AVERAGE(M6:M17),-2) -> 600600 | O5: 갑철 입금 | P5: =SUM(P6:P9) -> 3540000 | R5: 경희 입금 | S5: =SUM(S6:S9) -> 1580000
B6: 46082 | C6: =SUM(D6:J6) -> 686890 | D6: 521900 | E6: 31710 | F6: 28600 | G6: =18900-15000 -> 3900 | I6: 54450 | J6: 46330 | K6: =SUM(E6:G6) -> 64210 | L6: =SUM(I6:J6) -> 100780 | M6: =C6-L6 -> 586110 | O6: 국민연금 | P6: 1700000 | R6: 기초연금 | S6: 280000
B7: 46054 | C7: =SUM(D7:J7) -> 746990 | D7: 584760 | E7: 31700 | F7: 28600 | G7: =18900-15000 -> 3900 | I7: 51700 | J7: 46330 | K7: =SUM(E7:G7) -> 64200 | L7: =SUM(I7:J7) -> 98030 | M7: =C7-L7 -> 648960 | O7: 기초연금 | P7: 140000 | R7: 상가임대/지수 | S7: 500000
B8: 46023 | C8: =SUM(D8:J8) -> 726690 | D8: 564460 | E8: 31700 | F8: 28600 | G8: =18900-15000 -> 3900 | I8: 51700 | J8: 46330 | K8: =SUM(E8:G8) -> 64200 | L8: =SUM(I8:J8) -> 98030 | M8: =C8-L8 -> 628660 | O8: 주택연금 | P8: 2200000 | R8: 보선 생활비 | S8: 300000
B9: 45992 | C9: =SUM(D9:J9) -> 680970 | D9: 518740 | E9: 31700 | F9: 28600 | G9: =18900-15000 -> 3900 | I9: 51700 | J9: 46330 | K9: =SUM(E9:G9) -> 64200 | L9: =SUM(I9:J9) -> 98030 | M9: =C9-L9 -> 582940 | O9: 경희 이체 | P9: -500000 | R9: 갑철 이체 | S9: =-P9 -> 500000
B10: 45962 | C10: =SUM(D10:J10) -> 622260 | D10: 460030 | E10: 31700 | F10: 28600 | G10: =18900-15000 -> 3900 | I10: 51700 | J10: 46330 | K10: =SUM(E10:G10) -> 64200 | L10: =SUM(I10:J10) -> 98030 | M10: =C10-L10 -> 524230 | O10: 갑철 자동출금 | P10: =SUM(P11:P19) -> 2102000 | R10: 경희 자동출금 | S10: =SUM(S11:S13) -> 1040000
B11: 45931 | C11: =SUM(D11:J11) -> 650850 | D11: 482890 | E11: 31700 | F11: 28600 | G11: =18900-15000 -> 3900 | I11: 57200 | J11: 46560 | K11: =SUM(E11:G11) -> 64200 | L11: =SUM(I11:J11) -> 103760 | M11: =C11-L11 -> 547090 | O11: 국민카드 | P11: 750000 | R11: 가족회비/어머님 | S11: 400000
B12: 45901 | C12: =SUM(D12:J12) -> 864760 | D12: 725930 | E12: 31700 | F12: 28600 | G12: =18900-15000 -> 3900 | I12: 51700 | J12: 22930 | K12: =SUM(E12:G12) -> 64200 | L12: =SUM(I12:J12) -> 74630 | M12: =C12-L12 -> 790130 | O12: 보험 | P12: =30000+370000 -> 400000 | R12: 상가대출/노란우산 | S12: 520000
B13: 45870 | C13: =SUM(D13:J13) -> 780650 | D13: 618420 | E13: 31700 | F13: 28600 | G13: =18900-15000 -> 3900 | I13: 51700 | J13: 46330 | K13: =SUM(E13:G13) -> 64200 | L13: =SUM(I13:J13) -> 98030 | M13: =C13-L13 -> 682620 | O13: 보험대출 이자 | P13: 32000 | R13: 건강보험 | S13: 120000
B14: 45839 | C14: =SUM(D14:J14) -> 593580 | D14: 431350 | E14: 31700 | F14: 28600 | G14: =18900-15000 -> 3900 | I14: 51700 | J14: 46330 | K14: =SUM(E14:G14) -> 64200 | L14: =SUM(I14:J14) -> 98030 | M14: =C14-L14 -> 495550 | O14: SKT | P14: 60000
B15: 45809 | C15: =SUM(D15:J15) -> 632780 | D15: 467800 | E15: 31700 | F15: 28600 | G15: =18900-15000 -> 3900 | I15: 54450 | J15: 46330 | K15: =SUM(E15:G15) -> 64200 | L15: =SUM(I15:J15) -> 100780 | M15: =C15-L15 -> 532000 | O15: 백세회 | P15: 20000
B16: 45778 | C16: =SUM(D16:J16) -> 659360 | D16: 497130 | E16: 31700 | F16: 28600 | G16: =18900-15000 -> 3900 | I16: 51700 | J16: 46330 | K16: =SUM(E16:G16) -> 64200 | L16: =SUM(I16:J16) -> 98030 | M16: =C16-L16 -> 561330 | O16: 경조/세금/보험 | P16: =ROUND((600000+400000+4500000+1000000)/12+300000,-4) -> 840000 | Q16: 자동차세/재산세/경조비
B17: 45748 | C17: =SUM(D17:J17) -> 725160 | D17: 562930 | E17: 31700 | F17: 28600 | G17: =18900-15000 -> 3900 | I17: 51700 | J17: 46330 | K17: =SUM(E17:G17) -> 64200 | L17: =SUM(I17:J17) -> 98030 | M17: =C17-L17 -> 627130 | O17: BC카드 | P17: 0
O18: 우체국보험 | P18: =54000*0 -> 0 | Q18: 26.6월 만기
B19: 2026년 6월부터 | E19: 31700 | F19: 28600 | G19: =18900-15000 -> 3900 | H19: 17280 | I19: 38680 | J19: 31230 | K19: =SUM(E19:H19) -> 81480 | L19: =SUM(I19:J19) -> 69910 | O19: 상가관리비 | P19: =120000*0 -> 0 | Q19: 26.6월 만기/7월부터 태희납부
K20: =K19-K17 -> 17280 | L20: =L19-L17 -> -28120
I22: =I28+12000 -> 31800 | M22: =M25-M23 -> -65465
B23: 2026.04-27.03 | L23: 계산 가정 | M23: 650000
B24: 월별 | C24: 평균 | D24: 관리비 | E24: 코웨이-1 | F24: 코웨이-2 | G24: 코웨이-3 | H24: 코웨이-4 | I24: SK-1 | J24: SK-2 | K24: 코웨이 | L24: 통신비 | M24: 통신비외
B25: 월평균 | C25: =SUM(C26:C37)/COUNT(C26:C37) -> 646611.67 | D25: =SUM(D26:D37)/COUNT(D26:D37) -> 507398.33 | E25: =SUM(E26:E37)/COUNT(E26:E37) -> 31706.667 | F25: =SUM(F26:F37)/COUNT(F26:F37) -> 28600 | G25: =SUM(G26:G37)/COUNT(G26:G37) -> 3900 | H25: =SUM(H26:H37)/COUNT(H26:H37) -> 19395 | I25: =SUM(I26:I37)/COUNT(I26:I37) -> 28250 | J25: =SUM(J26:J37)/COUNT(J26:J37) -> 33826.667 | ... M25: =SUM(M26:M37)/COUNT(M26:M37) -> 584535
B26: 46113 | C26: =SUM(D26:J26) -> 673660 | D26: 514420 | E26: 31710 | F26: 28600 | G26: =18900-15000 -> 3900 | I26: 51700 | J26: =46330-3000 -> 43330 | K26: =SUM(E26:H26) -> 64210 | L26: =SUM(I26:J26) -> 95030 | M26: =C26-L26 -> 578630
B27: 46143 | C27: =SUM(D27:J27) -> 673320 | D27: 536290 | E27: 31700 | F27: 28600 | G27: =18900-15000 -> 3900 | I27: 38600 | J27: 34230 | K27: =SUM(E27:H27) -> 64200 | L27: =SUM(I27:J27) -> 72830 | M27: =C27-L27 -> 600490
B28: 46174 | C28: =SUM(D28:J28) -> 571320 | D28: 438690 | E28: 31700 | F28: 28600 | G28: =18900-15000 -> 3900 | H28: 17280 | I28: 19800 | J28: =34350-3000 -> 31350 | K28: =SUM(E28:H28) -> 81480 | L28: =SUM(I28:J28) -> 51150 | M28: =C28-L28 -> 520170
B29: 46204 | C29: =SUM(D29:J29) -> 551370 | D29: 415910 | E29: 31710 | F29: 28600 | G29: =18900-15000 -> 3900 | H29: 20100 | I29: 19800 | J29: =34350-3000 -> 31350 | K29: =SUM(E29:H29) -> 84310 | L29: =SUM(I29:J29) -> 51150 | M29: =C29-L29 -> 500220
B30: 46235 | C30: =SUM(D30:J30) -> 654020 | D30: 518560 | E30: 31710 | F30: 28600 | G30: =18900-15000 -> 3900 | H30: 20100 | I30: 19800 | J30: =34350-3000 -> 31350 | K30: =SUM(E30:H30) -> 84310 | L30: =SUM(I30:J30) -> 51150 | M30: =C30-L30 -> 602870 | N30: 갑철 통신비 별도 : 54,000원 계좌자동이체
B31: 46266 | C31: =SUM(D31:J31) -> 755980 | D31: 620520 | E31: 31710 | F31: 28600 | G31: =18900-15000 -> 3900 | H31: 20100 | I31: 19800 | J31: =34350-3000 -> 31350 | K31: =SUM(E31:H31) -> 84310 | L31: =SUM(I31:J31) -> 51150 | M31: =C31-L31 -> 704830
B32: 46296
B33: 46327
B34: 46357
B35: 46388
B36: 46419
B37: 46447
B42: 편의점 절감금액 | H42: 편의점 점감금액 / 금연
C43: 소비량 | D43: 절감 | E43: 세븐 | F43: 일반/기준 | I43: 소비량 | J43: 절감 | K43: 세븐
B44: 월간 | D44: =D45*30 -> -52500 | E44: =E45*30 -> 225000 | F44: =F45*30 -> 277500 | H44: 월간 | J44: =J45*30 -> -187500 | K44: =K45*30 -> 90000
B45: 일일 | D45: =SUM(D46:D48) -> -1750 | E45: =SUM(E46:E48) -> 7500 | F45: =SUM(F46:F48) -> 9250 | H45: 일일 | J45: =SUM(J46:J48) -> -6250 | K45: =SUM(K46:K48) -> 3000
B46: 담배 | C46: 1 | D46: =E46-F46 -> 0 | E46: =4500*$C46 -> 4500 | F46: =4500*$C46 -> 4500 | H46: 담배 | I46: 0 | J46: =K46-F46 -> -4500 | K46: =4500*$I46 -> 0
...

Sheet 실사용현황
B2: 100만시트 기준 | D2: <<누계>> | E2: 26년 4월 | F2: 26년 5월 | G2: 26년 6월 | H2: 26년 7월 | I2: 26년 8월 | J2: 26년 9월 | K2: 26년 10월 | M2: 26년 11월
C4: =D4/7 -> -224320.57 | D4: =SUM(E4:J4) -> -1570244 | E4: =SUM(E7,E11,E15,E19,E24) -> -331370 | F4: =SUM(F7,F11,F15,F19,F24) -> -849510 | G4: =SUM(G7,G11,G15,G19,G24) -> 640170 | H4: =SUM(H7,H11,H15,H19,H24) -> -667480 | I4: =SUM(I7,I11,I15,I19,I24) -> 216502 | J4: =SUM(J7,J11,J15,J19,J24) -> -578556 | K4: 월말에 계산 | M4: =SUM(M7,M11,M15,M19,M24) -> -2100000
K5: =SUM(K7,K11,K15,K19,K24) -> -687338
B6: 관리비/코웨이 사용현황 : 월65만원 계산
B7: 관리비 잉여금액 | D7: =SUM(E7:K7) -> -439920 | E7: =E8-650000 -> -71370 | F7: =F8-650000 -> -49510 | G7: =G8-650000 -> -129830 | H7: =H8-650000 -> -149780 | I7: =I8-650000 -> -47130 | J7: =J8-650000 -> 54830 | K7: =K8-650000 -> -47130 | M7: =M8-650000 -> -650000
C8: 사용금액 | D8: =SUM(E8:K8) -> 4110080 | E8: =관리비!M26 -> 578630 | F8: =관리비!M27 -> 600490 | G8: =관리비!M28 -> 520170 | H8: =관리비!M29 -> 500220 | I8: =관리비!M30 -> 602870 | J8: =관리비!M31 -> 704830 | K8: =I8 -> 602870
B10: 차량수리비 사용현황 : 월10만원 계산
B11: 차량수리비 잉여금액 | D11: =SUM(E11:K11) -> -130000 | E11: =E12-100000 -> -100000 | F11: =F12-100000 -> -100000 | G11: =G12-100000 -> -100000 | H11: =H12-100000 -> -100000 | I11: =I12-100000 -> -100000 | J11: =J12-100000 -> 470000 | K11: =K12-100000 -> -100000 | M11: =M12-100000 -> -100000
C12: 사용금액 | D12: =SUM(E12:K12) -> 570000 | J12: 570000
B14: 여행비 사용현황 : 월20만원 계산
B15: 여행비 잉여금액 | D15: =SUM(E15:K15) -> -1000000 | E15: =E16-200000 -> -200000 | F15: =F16-200000 -> -200000 | G15: =G16-200000 -> -200000 | H15: =H16-200000 -> -200000 | I15: =I16-200000 -> -200000 | J15: =J16-200000 -> -200000 | K15: =K16-200000 -> 200000 | M15: =M16-200000 -> -200000
C16: 사용금액 | D16: =SUM(E16:K16) -> 400000 | E16: 0 | F16: 0 | G16: 0 | H16: 0 | I16: 0 | J16: 0 | K16: =400000+1400000-1400000 -> 400000
B18: 경조사비 사용현황 : 월30만원 계산
B19: 경조사비 차이금액 | D19: =SUM(E19:K19) -> 700000 | E19: =E20-300000 -> -200000 | F19: =F20-300000 -> -200000 | G19: =G20-300000 -> 300000 | H19: =H20-300000 -> -100000 | I19: =I20-300000 -> -100000 | J19: =J20-300000 -> 900000 | K19: =K20-300000 -> 100000 | M19: =M20-300000 -> -200000 | O19: 조카들 결혼 각200만원 예상 : 필요시 보험대출로 선진행 필요
C20: 사용금액 | D20: =SUM(E20:K20) -> 2800000 | E20: 100000 | F20: 100000 | G20: =200000+100000+300000 -> 600000 | H20: 200000 | I20: 200000 | J20: =1000000+200000 -> 1200000 | K20: =200000+200000 -> 400000 | M20: =100000 -> 100000
B22: 생활비 사용현황 : 월100만 시트 계산 | K22: 46299
B24: 100만초과 갑철기본+사용가능 | D24: =SUM(E24:K24) -> -1387662 | E24: =E27-E25 -> 240000 | F24: =F27-F25 -> -300000 | G24: =G27-G25 -> 770000 | H24: =H27-H25 -> -117700 | I24: =I27-I25 -> 663632 | J24: =J27-J25 -> -1803386 | K24: =K27-K25 -> -840208 | M24: =M27-M25 -> -950000
C25: 사용가능금/기본포함 | D25: =SUM(E25:I25) -> 7500000 | E25: 1500000 | F25: 1500000 | G25: 1500000 | H25: 1500000 | I25: 1500000 | J25: 1500000 | K25: 1500000 | M25: 1500000
B27: 전체 사용금액 | D27: =SUM(E27:K27) -> 9112338 | E27: =E28-E29-E30 -> 1740000 | F27: =F28-F29-F30 -> 1200000 | G27: =G28-G29-G30 -> 2270000 | H27: =H28-H29-H30 -> 1382300 | I27: =I28-I29-I30 -> 2163632 | J27: =J28-J29-J30 -> -303386 | K27: =K28-K29-K30 -> 659792 | M27: =M28-M29-M30 -> 550000 | O27: 추가 절감 - 8월
C28: 총사용금액 | E28: 2500000 | F28: 2500000 | G28: 2500000 | H28: =SUM(H32,H37) -> 2867764 | I28: =SUM(I32,I37) -> 2496132 | J28: =SUM(J32,J37) -> 2337274 | K28: =SUM(K32,K37) -> 1049812 | M28: =SUM(M32,M37) -> 550000 | O28: 캔거피 대량구입 : TOP 200ml 72캔 - 50,400원(배송비포함)
C29: 익월로 이월금액 | H29: =H82 -> 430000 | I29: =I82 -> 142500 | J29: =J82 -> 0 | K29: =K82 -> 0 | M29: =M82 -> 0
C30: 부가수입 | E30: =E39 -> 760000 | F30: =F39 -> 1300000 | G30: =G39 -> 230000 | H30: =H39 -> 1055464 | I30: =I39 -> 190000 | J30: =J39 -> 2640660 | K30: =K39 -> 390020 | M30: =M39 -> 0 | O30: 월 72캔 마실경우 (일2.4캔)
B32: 경희 사용금액 | E32: =SUM(E33:E35) -> 650000 | F32: =SUM(F33:F35) -> 650000 | G32: =SUM(G33:G35) -> 650000 | H32: =SUM(H33:H35) -> 970000 | I32: =SUM(I33:I35) -> 450000 | J32: =SUM(J33:J35) -> 525000 | K32: =SUM(K33:K35) -> 550000 | M32: =SUM(M33:M35) -> 550000 | O32: 편의점/무할인 | P32: =72*1500 -> 108000
C33: 이음카드(생활/마사지) | E33: =25000*4+200000 -> 300000 | F33: =25000*4+200000 -> 300000 | G33: =25000*4+200000 -> 300000 | H33: =25000*10+200000+70000 -> 520000 | I33: =25000*0+200000 -> 200000 | J33: =25000*3+200000 -> 275000 | K33: =25000*4+200000 -> 300000 | M33: =25000*4+200000 -> 300000 | O33: 편의점/2+1 | P33: =(72/3*2)*1500 -> 72000 | Q33: =P33-P32 -> -36000
C34: 병원(환급85%)/기타 | E34: =250000*0.2 -> 50000 | F34: =250000*0.2 -> 50000 | G34: =250000*0.2 -> 50000 | H34: =250000*0.2+100000 -> 150000 | I34: =250000*0.2 -> 50000 | J34: =250000*0.2 -> 50000 | K34: =250000*0.2 -> 50000 | M34: =250000*0.2 -> 50000 | O34: 대량구입/72캔구입 | P34: =(23700*2+3000)*72/(36*2) -> 50400 | Q34: =P34-P31 -> 50400 | R34: =P34-P32 -> -57600
C35: 쇼핑 / 예상금액 | E35: 300000 | F35: 300000 | G35: 300000 | H35: =100000+200000 -> 300000 | I35: 200000 | J35: 200000 | K35: 200000 | M35: 200000 | O35: 대량구입/72캔구입 | P35: =(23700*2+3000)*72/(36*2) -> 50400 | Q35: =P35-P32 -> -57600 | R35: =P35-P33 -> -21600
B37: 갑철 사용금액 | E37: =E28-E32 -> 1850000 | F37: =F28-F32 -> 1850000 | G37: =G28-G32 -> 1850000 | H37: =SUM(H46,H50,H54,H87,H78,H80) -> 1897764 | I37: =SUM(I46,I50,I54,I87,I78,I80) -> 2046132 | J37: =SUM(J46,J50,J54,J87,J78,J80) -> 1812274 | K37: =SUM(K46,K50,K54,K87,K78,K80) -> 499812 | M37: =SUM(M46,M50,M54,M87,M78,M80) -> 0 | O37: # 하절기에는 편의점 할인판매 없음
B39: 부가 수입 | E39: =SUM(E40:E44) -> 760000 | F39: =SUM(F40:F44) -> 1300000 | G39: =SUM(G40:G44) -> 230000 | H39: =SUM(H40:H44) -> 1055464 | I39: =SUM(I40:I44) -> 190000 | J39: =SUM(J40:J44) -> 2640660 | K39: =SUM(K40:K44) -> 390020 | M39: =SUM(M40:M44) -> 0
C40: 이음카드 캐시백 | E40: 60000 | F40: 200000 | G40: 200000 | H40: 200000 | J40: 54460 | K40: 5020
C41: 보험 배당/실손 | H41: 440000 | J41: 186200
C42: 경희 부가세 환급 | H42: =215464 -> 215464
C43: 기타 (조의금) | G43: 30000 | I43: 20000 | J43: 2200000
C44: 보선/지수 용돈 | E44: =200000+500000 -> 700000 | F44: =600000+500000 -> 1100000 | H44: 200000 | I44: =30000+100000+40000 -> 170000 | J44: 200000 | K44: 385000
B46: 전월 상품이월 | H46: =SUM(H47:H48) -> 214000 | I46: =SUM(I47:I48) -> 430000 | J46: =SUM(J47:J48) -> 142500 | K46: =SUM(K47:K48) -> 0 | M46: =SUM(M47:M48) -> 0
C47: 갑철 담배/생필품 | H47: 90000 | I47: =H83 -> 210000 | J47: =I83 -> 67500
C48: 경희 주유 | H48: 124000 | I48: =H84 -> 220000 | J48: =I84 -> 75000
B50: 이음카드 사용 | H50: =H51 -> 726230 | I50: =I51 -> 292950 | J50: =J51 -> 782690 | K50: =K51 -> 63500 | M50: =M51 -> 0
C51: 총사용금액 | H51: =751230-25000 -> 726230 | I51: 292950 | J51: 782690 | K51: 63500
C52: 캐시백 사용 | H52: 147850
B54: 카드/현금/상품권 | H54: =SUM(H55:H60) -> 200160 | I54: =SUM(I55:I76) -> 1124309 | J54: =SUM(J55:J76) -> 787084 | K54: =SUM(K55:K76) -> 436312 | M54: =SUM(M55:M76) -> 0
...

Sheet 주택연금26년_상가31년_100만
B2: 2024년4월 - 2025년11월 Balance: 사용가능액 월150만원 | G2: 법인카드사용분 월50만원
B3: 월 Balance | C3: 사용가능 | D3: 수입 | F3: 지출
B4: 25년10월 기준 | C4: =SUM(D4,F4) -> 1895000 | D4: =SUM(E5:E8) -> 5950000 | F4: =SUM(G5:G13) -> -4055000
D5: 국민연금 | E5: 1650000 | F5: 관리비 | G5: -700000
D6: 상가임대료 | E6: 1000000 | F6: 어머님/회비 | G6: -400000
D7: 급여 | E7: 2800000 | F7: 통신/코웨이 | G7: -300000
D8: 법인카드 사용 | E8: 500000 | F8: 보험 | G8: =-(460000+200000)-100000 -> -760000
F9: 경조사비/세금 | G9: -400000
F10: 상가이자/노란우산 | G10: =-(120000000*0.0425/12)-120000 -> -545000
F11: 보험대출이자 | G11: -225000
F12: 건강보험(갑철) | G12: -225000
F13: 식비 | G13: -500000
B15: 2025년12월-2026년3월 : 0년4개월(4개월)
B16: 월 Balance | C16: 사용가능 | D16: 수입 | F16: 지출 | H16: 상가임대 : 초기 수개월 무료 / 월세는 100만원으로 계약해야함
C17: 1500000 | D17: =SUM(E18:E24) -> 5125000 | F17: =SUM(G18:G28) -> -3625000 | H17: 태희 사무실로 활용(계약없이) / 임대료는 상황에 따라 현금으로
B18: 가용현금 | C18: =C19+C20+C21 -> 34500000 | D18: 국민연금 | E18: 1690000 | F18: 관리비 | G18: -700000 | H18: - 태희 미사용시, 보선 공간임대업 / 무상임대로 계약도 검토
B19: 경희 보유중 | C19: =-3000000+4000000 -> 1000000 | D19: 상가임대료 | E19: 0 | F19: 어머님/회비 | G19: -400000
B20: KC정리잔금 | C20: =현자산!E14 -> 18500000 | D20: 기초연금(2명) | F20: 통신 | G20: -100000 | H20: 갑철 통신비 감소 (약정 변경 122,000-> 71,000)
B21: 장모님 | C21: 15000000 | D21: 보선생활비 | E21: 300000 | F21: 상가이자/노란우산 | G21: =-ROUND((113000000*0.0425/12)+120000,-3) -> -520000
B22: 보험대출 상환완료 | C22: -50000000 | D22: 지수생활비 | F22: 보험/자동차(수리) | G22: =-400000-210000-200000 -> -810000 | H22: 만기 : 경희 30만 26.2월, 경희 17만 28.2월, 갑철 21만 30년9월
B23: 상가대출 상환완료 | C23: -2400000 | D23: 급여 | E23: 0 | F23: 경조사비 | G23: -100000
B24: 보험대출 재진행 | C24: =9370000 -> 9370000 | D24: 현금사용 | E24: =(-F17+C17-SUM(E18:E23)) -> 3135000 | F24: 자동차세/연납 | G24: =-600000/3 -> -200000
B25: 현금사용 | C25: =-E24*4 -> -12540000 | F25: 보험대출이자 | G25: =-ROUND(C24*0.04/12,-3) -> -31000 | H25: 25.12.18 5천만 전액상환 / 26.1.7일 937만 재대출(주식투자),
B26: 잔여현금 | C26: =C18+C24+C25+E28 -> 19930000 | D26: 주식투자중 | E26: 29400000 | F26: 갑철기본 | G26: -500000
D27: 46104 | E27: 18000000 | F27: 건강보험(갑철) | G27: =-114000 -> -114000 | H27: 경희 직장임의계속가입/갑철 피부양자등록(26.1월부터)
E28: =E27-E26 -> -11400000 | F28: 상가관리비 | G28: =-(150000*12)/12 -> -150000 | H28: 갑철 피부양자 가능 (25년 총19,985,760 : 수령1,657,830(세금7,650포함))
H29: 26년 2.1% 인상되면, 피부양자 자격상실 가능 > 경희와 통합하여 지역가입???
B31: 2026년4월 주택연금 가입 / 만65세 | M31: Q) 주택이 재해로 멸실되면 주택연금 못받나?
B32: 26.4월-31.3월 | D32: 31년4월 이후 | F32: 주택가격 | G32: 초기증액형 | H32: : 인출시는 주택금융공사와 진행필요 | M32: 거주 주택이 재해나 화재로 멸실되도 연금을 계속 받을 수 있다. (즉시 공사에 알리고 협의필요)
B33: =ROUND(2203450*1,-4) -> 2200000 | D33: =ROUND(1542420*1,-4) -> 1540000 | F33: 685000000 | G33: 5년 | H33: 26/3/30일 신청 // '26/4/29일부터 매월29일 입금 (26/4/24 국민은행 서류작성 완료) | M33: 다만, 거주를 지속해야 연금이 나오기 때문에 주택을 보수거나 새로 지어야 한다. (3년내)
B35: 26년4월 - 27년3월 : 1년0개월(12개월) | E35: 기초연금자산(주택연금대출: 누적지급금) | F35: =ROUND(C38+C46+(650000000+250000000-0),-6) -> 1111000000 | G35: =ROUND(C45+C46+(650000000+250000000-'보증잔액 Table'!G4),-6) -> 1080000000 | H35: 주택가 상승시 해지/매도/33평매입&재가입 진행필요 (받은연금-보증잔액 : 초기에는 크지않음)
B36: 월 Balance | C36: 사용가능 | D36: 수입 | F36: 지출 | H36: 사무실 계약 : 월30만원(부가세별도/세금계산서 발행) + 현금 월20만원
C37: =C17-500000 -> 1000000 | D37: =SUM(E38:E44) -> 4589500 | F37: =SUM(G38:G49) -> -3589500 | H37: - 30만원이상시 감액 (50만원시 월-17.5만) : 실사업소득으로는 50만원도 무관하나, 계약서금액으로 선반영함
B38: 가용현금 | C38: =C26+C39+(300000*2+140000) -> 20670000 | D38: 국민연금 | E38: =ROUND(E18*1,-4) -> 1690000 | F38: 관리비/코웨이 | G38: -650000 | H38: 보선/서연 주소이전후 에너지바우처 신청완료 / 25.4-26.3월 평균 : 600,600원 (26.6월부터 비데2 +17,280)
B39: 갑철리빙케어해지 | D39: 주택연금 | E39: =B33 -> 2200000 | F39: 어머님/회비 | G39: =-ROUND((400000*5+0)/12,-3) -> -167000 | H39: <기초연금 소득인정액(26/7/3일 월세30만포함) 352만원 - 26년기준 395만 & 27년 기준중위소득(419만) 90%(377만)에도 해당됨
B40: 사무실준비/차량수리 | C40: =ROUND(-(230000+1500000)-1170000-(3100000-1000000),-4) -> -5000000 | D40: 기초연금(2명) | E40: =ROUND(349700*(1+0.5)*0.8+(12000*2)*11/12,0) -> 441640 | F40: 통신 | G40: =-55000-32000-34000-5500-24000 -> -150500 | H40: 갑철/BTV/경희/제네시스, 26/4월 Btv 약정 축소 -38,000원, 기초연금 통신비감면 24,000원은 기초연금에 포함
B41: 보험대출 상환 | D41: 상가임대/지수 | E41: =ROUND((500000*4+500000*6)/12,-3) -> 417000 | F41: 상가이자/노란우산 | G41: =-ROUND(((115640000+0)*0.0412/12)+120000,-3) -> -517000 | H41: * 26.7월 경희우체국보험 만기배당금 44만원 수령 (렌지후드교체로 사용)
B42: 상가대출 상환 | C42: -5000000 | D42: 보선 생활비 | E42: 300000 | F42: 보험 | G42: =ROUND(-165000-207000-30000-19900-(54000*3/12),-3) -> -435000 | H42: 만기 : 경희 17만 28.2월, 갑철 10만 30년9월(11만 계속). 경희우체국 26.6월(80세보장), 운전자보험 3만, 화재보험 2만
B43: 보험대출 재진행 | D43: 급여 | F43: 경조사비/세금 | G43: =ROUND(-300000-(600000+360000+100000+250000)/12,-3) -> -409000 | H43: 경조사비 월30만원, 재산세 년60만원 & 상가 36만원 & 종소세 10만 & 수수료 25만 /// 조카6명 결혼 1,200만원 필요(추가소요 예상)
B44: 현금사용/저축 | C44: =-E44*12 -> 5509680 | D44: 현금사용 | E44: =(-F37+C37-SUM(E38:E43)) -> -459140 | F44: 차보험/수리/세금 | G44: =-ROUND(1000000/12,-3)-ROUND(1200000/12,-3)-ROUND(600000/12,-3) -> -233000 | H44: 보험 : 5월 100만원(주차장사고로 인상?), 년수리비 120만원. 자동차세 년60만
...

Sheet 주택연금26년_상가31년_100만(구)
B2: 2024년4월 - 2025년11월 Balance: 사용가능액 월150만원 | G2: 법인카드사용분 월50만원
B3: 월 Balance | C3: 사용가능 | D3: 수입 | F3: 지출
B4: 25년10월 기준 | C4: =SUM(D4,F4) -> 1895000 | D4: =SUM(E5:E8) -> 5950000 | F4: =SUM(G5:G13) -> -4055000
D5: 국민연금 | E5: 1650000 | F5: 관리비 | G5: -700000
D6: 상가임대료 | E6: 1000000 | F6: 어머님/회비 | G6: -400000
D7: 급여 | E7: 2800000 | F7: 통신/코웨이 | G7: -300000
D8: 법인카드 사용 | E8: 500000 | F8: 보험 | G8: =-(460000+200000)-100000 -> -760000
F9: 경조사비/세금 | G9: -400000
F10: 상가이자/노란우산 | G10: =-(120000000*0.0425/12)-120000 -> -545000
F11: 보험대출이자 | G11: -225000
F12: 건강보험(갑철) | G12: -225000
F13: 식비 | G13: -500000
B15: 2025년12월-2026년3월 : 0년4개월(4개월)
B16: 월 Balance | C16: 사용가능 | D16: 수입 | F16: 지출 | H16: 상가임대 : 초기 수개월 무료 / 월세는 100만원으로 계약해야함
C17: 1500000 | D17: =SUM(E18:E24) -> 5125000 | F17: =SUM(G18:G28) -> -3625000 | H17: 태희 사무실로 활용(계약없이) / 임대료는 상황에 따라 현금으로
B18: 가용현금 | C18: =C19+C20+C21 -> 34500000 | D18: 국민연금 | E18: 1690000 | F18: 관리비 | G18: -700000 | H18: - 태희 미사용시, 보선 공간임대업 / 무상임대로 계약도 검토
B19: 경희 보유중 | C19: =-3000000+4000000 -> 1000000 | D19: 상가임대료 | E19: 0 | F19: 어머님/회비 | G19: -400000
B20: KC정리잔금 | C20: =현자산!E14 -> 18500000 | D20: 기초연금(2명) | F20: 통신 | G20: -100000 | H20: 갑철 통신비 감소 (약정 변경 122,000-> 71,000)
B21: 장모님 | C21: 15000000 | D21: 보선생활비 | E21: 300000 | F21: 상가이자/노란우산 | G21: =-ROUND((113000000*0.0425/12)+120000,-3) -> -520000
B22: 보험대출 상환완료 | C22: -50000000 | D22: 지수생활비 | F22: 보험/자동차(수리) | G22: =-400000-210000-200000 -> -810000 | H22: 만기 : 경희 30만 26.2월, 경희 17만 28.2월, 갑철 21만 30년9월
B23: 상가대출 상환완료 | C23: -2400000 | D23: 급여 | E23: 0 | F23: 경조사비 | G23: -100000
B24: 보험대출 재진행 | C24: =9370000 -> 9370000 | D24: 현금사용 | E24: =(-F17+C17-SUM(E18:E23)) -> 3135000 | F24: 자동차세/연납 | G24: =-600000/3 -> -200000
B25: 현금사용 | C25: =-E24*4 -> -12540000 | F25: 보험대출이자 | G25: =-ROUND(C24*0.04/12,-3) -> -31000 | H25: 25.12.18 5천만 전액상환 / 26.1.7일 937만 재대출(주식투자),
B26: 잔여현금 | C26: =C18+C24+C25+E28 -> 19930000 | D26: 주식투자중 | E26: 29400000 | F26: 갑철기본 | G26: -500000
D27: 46104 | E27: 18000000 | F27: 건강보험(갑철) | G27: =-114000 -> -114000 | H27: 경희 직장임의계속가입/갑철 피부양자등록(26.1월부터)
E28: =E27-E26 -> -11400000 | F28: 상가관리비 | G28: =-(150000*12)/12 -> -150000 | H28: 갑철 피부양자 가능 (25년 총19,985,760 : 수령1,657,830(세금7,650포함))
H29: 26년 2.1% 인상되면, 피부양자 자격상실 가능 > 경희와 통합하여 지역가입???
B31: 2026년4월 주택연금 가입 / 만65세 | G31: 주택평가액 7억으로 고려 / 상가매도 태희상황으로 결정 | H31: 1,5억 수시인출 가능 : 이자는 연금에서 삭감 / 상환시 연금 정상화됨 | M31: Q) 주택이 재해로 멸실되면 주택연금 못받나?
B32: 26.4월-31.3월 | D32: 31년4월 이후 | F32: 주택가격 | G32: 초기증액형 | H32: : 인출시는 주택금융공사와 진행필요 | M32: 거주 주택이 재해나 화재로 멸실되도 연금을 계속 받을 수 있다. (즉시 공사에 알리고 협의필요)
B33: =ROUND(2203450*1,-4) -> 2200000 | D33: =ROUND(1542420*1,-4) -> 1540000 | F33: 685000000 | G33: 5년 | H33: 26/3/30일 신청 // '26/4/29일부터 매월29일 입금 (26/4/24 국민은행 서류작성 완료) | M33: 다만, 거주를 지속해야 연금이 나오기 때문에 주택을 보수거나 새로 지어야 한다. (3년내)
B35: 26년4월 - 27년3월 : 1년0개월(12개월) | G35: 주택가 상승시 해지 & 매도 / 작은평 매입 / 주택연금 재가입 가능 | H35: 주택가 상승시 해지/매도/33평매입&재가입 진행필요 (받은연금-보증잔액 : 초기에는 크지않음)
B36: 월 Balance | C36: 사용가능 | D36: 수입 | F36: 지출 | H36: 사무실 계약 : 월30만원(부가세별도/세금계산서 발행) + 현금 월20만원
C37: =C17-500000 -> 1000000 | D37: =SUM(E38:E44) -> 4671500 | F37: =SUM(G38:G49) -> -3671500 | H37: - 30만원이상시 감액 (50만원시 월-17.5만) : 실사업소득으로는 50만원도 무관하나, 계약서금액으로 선반영함
B38: 가용현금 | C38: =C26+C39+(300000*2+140000) -> 20670000 | D38: 국민연금 | E38: =ROUND(E18*1,-4) -> 1690000 | F38: 관리비/코웨이 | G38: -650000 | H38: 보선/서연 주소이전후 에너지바우처 신청완료 / 25.4-26.3월 평균 : 600,600원 (26.6월부터 비데2 +17,280)
B39: 갑철리빙케어해지 | D39: 주택연금 | E39: =B33 -> 2200000 | F39: 어머님/회비 | G39: =-ROUND((400000*5+50000*7)/12,-3) -> -196000 | H39: <기초연금 소득인정액(26/7/3일 월세30만 추가후) 352만원 - 27년 기준중위소득(419만원) 90%(377만원)에도 해당됨
B40: 사무실준비/차량수리 | C40: =ROUND(-(230000+1500000)-1170000-(3100000-1000000),-4) -> -5000000 | D40: 기초연금(2명) | E40: =ROUND(349700*(1+0.5)*0.8+(12000*2)*11/12,0) -> 441640 | F40: 통신 | G40: =-55000-32000-34000-5500-24000 -> -150500 | H40: 갑철/BTV/경희/제네시스, 26/4월 Btv 약정 축소 -38,000원, 기초연금 통신비감면 24,000원은 기초연금에 포함
B41: 보험대출 상환 | D41: 상가임대/지수 | E41: =ROUND((500000*12+700000)/12,-3) -> 558000 | F41: 상가이자/노란우산 | G41: =-ROUND(((115640000+0)*0.0412/12)+120000,-3) -> -517000 | H41: * 26.7월 경희우체국보험 만기배당금 44만원 수령 (렌지후드교체로 사용)
B42: 상가대출 상환 | C42: -5000000 | D42: 보선 생활비 | E42: 300000 | F42: 보험 | G42: =ROUND(-165000-207000-30000-19900-(54000*3/12),-3) -> -435000 | H42: 만기 : 경희 17만 28.2월, 갑철 10만 30년9월(11만 계속). 경희우체국 26.6월(80세보장), 운전자보험 3만, 화재보험 2만
B43: 보험대출 재진행 | D43: 급여 | F43: 경조사비/세금 | G43: =ROUND(-300000-(600000+360000+100000+250000)/12,-3) -> -409000 | H43: 경조사비 월30만원, 재산세 년60만원 & 상가 36만원 & 종소세 10만 & 수수료 25만
B44: 현금사용/저축 | C44: =-E44*12 -> 6217680 | D44: 현금사용 | E44: =(-F37+C37-SUM(E38:E43)) -> -518140 | F44: 차보험/수리/세금 | G44: =-ROUND(1000000/12,-3)-ROUND(1200000/12,-3)-ROUND(600000/12,-3) -> -233000 | H44: 보험 : 5월 100만원(주차장사고로 인상?), 년수리비 120만원. 자동차세 년60만
...

Sheet 주택연금26년_상가31년_120만(구)
B2: 2024년4월 - 2025년11월 Balance: 사용가능액 월150만원 | G2: 법인카드사용분 월50만원
B3: 월 Balance | C3: 사용가능 | D3: 수입 | F3: 지출
B4: 25년10월 기준 | C4: =SUM(D4,F4) -> 1895000 | D4: =SUM(E5:E8) -> 5950000 | F4: =SUM(G5:G13) -> -4055000
D5: 국민연금 | E5: 1650000 | F5: 관리비 | G5: -700000
D6: 상가임대료 | E6: 1000000 | F6: 어머님/회비 | G6: -400000
D7: 급여 | E7: 2800000 | F7: 통신/코웨이 | G7: -300000
D8: 법인카드 사용 | E8: 500000 | F8: 보험 | G8: =-(460000+200000)-100000 -> -760000
F9: 경조사비/세금 | G9: -400000
F10: 상가이자/노란우산 | G10: =-(120000000*0.0425/12)-120000 -> -545000
F11: 보험대출이자 | G11: -225000
F12: 건강보험(갑철) | G12: -225000
F13: 식비 | G13: -500000
B15: 2025년12월-2026년3월 : 0년4개월(4개월)
B16: 월 Balance | C16: 사용가능 | D16: 수입 | F16: 지출 | H16: 상가임대 : 초기 수개월 무료 / 월세는 100만원으로 계약해야함
C17: 1500000 | D17: =SUM(E18:E24) -> 5125000 | F17: =SUM(G18:G28) -> -3625000 | H17: 태희 사무실로 활용(계약없이) / 임대료는 상황에 따라 현금으로
B18: 가용현금 | C18: =C19+C20+C21 -> 34500000 | D18: 국민연금 | E18: 1690000 | F18: 관리비 | G18: -700000 | H18: - 태희 미사용시, 보선 공간임대업 / 무상임대로 계약도 검토
B19: 경희 보유중 | C19: =-3000000+4000000 -> 1000000 | D19: 상가임대료 | E19: 0 | F19: 어머님/회비 | G19: -400000
B20: KC정리잔금 | C20: =현자산!E14 -> 18500000 | D20: 기초연금(2명) | F20: 통신 | G20: -100000 | H20: 갑철 통신비 감소 (약정 변경 122,000-> 71,000)
B21: 장모님 | C21: 15000000 | D21: 보선생활비 | E21: 300000 | F21: 상가이자/노란우산 | G21: =-ROUND((113000000*0.0425/12)+120000,-3) -> -520000
B22: 보험대출 상환완료 | C22: -50000000 | D22: 지수생활비 | F22: 보험/자동차(수리) | G22: =-400000-210000-200000 -> -810000 | H22: 만기 : 경희 30만 26.2월, 경희 17만 28.2월, 갑철 21만 30년9월
B23: 상가대출 상환완료 | C23: -2400000 | D23: 급여 | E23: 0 | F23: 경조사비 | G23: -100000
B24: 보험대출 재진행 | C24: =9370000 -> 9370000 | D24: 현금사용 | E24: =(-F17+C17-SUM(E18:E23)) -> 3135000 | F24: 자동차세/연납 | G24: =-600000/3 -> -200000
B25: 현금사용 | C25: =-E24*4 -> -12540000 | F25: 보험대출이자 | G25: =-ROUND(C24*0.04/12,-3) -> -31000 | H25: 25.12.18 5천만 전액상환 / 26.1.7일 937만 재대출(주식투자),
B26: 잔여현금 | C26: =C18+C24+C25+E28 -> 19930000 | D26: 주식투자중 | E26: 29400000 | F26: 갑철기본 | G26: -500000
D27: 46104 | E27: 18000000 | F27: 건강보험(갑철) | G27: =-114000 -> -114000 | H27: 경희 직장임의계속가입/갑철 피부양자등록(26.1월부터)
E28: =E27-E26 -> -11400000 | F28: 상가관리비 | G28: =-(150000*12)/12 -> -150000 | H28: 갑철 피부양자 가능 (25년 총19,985,760 : 수령1,657,830(세금7,650포함))
H29: 26년 2.1% 인상되면, 피부양자 자격상실 가능 > 경희와 통합하여 지역가입???
B31: 2026년4월 주택연금 가입 / 만65세 | G31: 주택평가액 7억으로 고려 / 상가매도 태희상황으로 결정 | H31: 1,5억 수시인출 가능 : 이자는 연금에서 삭감 / 상환시 연금 정상화됨 | M31: Q) 주택이 재해로 멸실되면 주택연금 못받나?
B32: 26.4월-31.3월 | D32: 31년4월 이후 | F32: 주택가격 | G32: 초기증액형 | H32: : 인출시는 주택금융공사와 진행필요 | M32: 거주 주택이 재해나 화재로 멸실되도 연금을 계속 받을 수 있다. (즉시 공사에 알리고 협의필요)
B33: =ROUND(2203450*1,-4) -> 2200000 | D33: =ROUND(1542420*1,-4) -> 1540000 | F33: 685000000 | G33: 5년 | H33: 26/3/30일 신청 // '26/4/29일부터 매월29일 입금 (26/4/24 국민은행 서류작성 완료) | M33: 다만, 거주를 지속해야 연금이 나오기 때문에 주택을 보수거나 새로 지어야 한다. (3년내)
B35: 26년4월 - 27년3월 : 1년0개월(12개월) | G35: 주택가 상승시 해지 & 매도 / 작은평 매입 / 주택연금 재가입 가능 | H35: 주택가 상승시 해지/매도/33평매입&재가입 진행필요 (받은연금-보증잔액 : 초기에는 크지않음)
B36: 월 Balance | C36: 사용가능 | D36: 수입 | F36: 지출 | H36: 사무실 계약 : 월30만원(부가세별도/세금계산서 발행) + 현금 월20만원
C37: =C17-300000 -> 1200000 | D37: =SUM(E38:E44) -> 5075500 | F37: =SUM(G38:G49) -> -3875500 | H37: - 30만원이상시 감액 (50만원시 월-17.5만) : 실사업소득으로는 50만원도 무관하나, 계약서금액으로 선반영함
B38: 가용현금 | C38: =C26+C39+(300000*2+140000) -> 20670000 | D38: 국민연금 | E38: =ROUND(E18*1,-4) -> 1690000 | F38: 관리비/코웨이 | G38: -650000 | H38: 보선/서연 주소이전후 에너지바우처 신청완료 / 25.4-26.3월 평균 : 600,600원 (26.6월부터 비데2 +17,280)
B39: 갑철리빙케어해지 | D39: 주택연금 | E39: =B33 -> 2200000 | F39: 어머님/회비 | G39: =-400000 -> -400000
B40: 사무실준비/차량수리 | C40: =ROUND(-(230000+1500000)-1170000-(3100000-1000000),-4) -> -5000000 | D40: 기초연금(2명) | E40: =ROUND(349700*(1+0.5)*0.8+(12000*2)*11/12,0) -> 441640 | F40: 통신 | G40: =-55000-32000-34000-5500-24000 -> -150500 | H40: 갑철/BTV/경희/제네시스, 26/4월 Btv 약정 축소 -38,000원, 기초연금 통신비감면 24,000원은 기초연금에 포함
B41: 보험대출 상환 | D41: 상가임대/지수 | E41: =ROUND((500000*12+700000)/12,-3) -> 558000 | F41: 상가이자/노란우산 | G41: =-ROUND(((115640000+0)*0.0412/12)+120000,-3) -> -517000 | H41: * 26.7월 경희우체국보험 만기배당금 44만원 수령 (렌지후드교체로 사용)
B42: 상가대출 상환 | C42: -3000000 | D42: 보선 생활비 | E42: 300000 | F42: 보험 | G42: =ROUND(-165000-207000-30000-19900-(54000*3/12),-3) -> -435000 | H42: 만기 : 경희 17만 28.2월, 갑철 10만 30년9월(11만 계속). 경희우체국 26.6월(80세보장), 운전자보험 3만, 화재보험 2만
B43: 보험대출 재진행 | D43: 급여 | E43: 0 | F43: 경조사비/세금 | G43: =ROUND(-300000-(600000+360000+100000+250000)/12,-3) -> -409000 | H43: 경조사비 월30만원, 재산세 년60만원 & 상가 36만원 & 종소세 10만 & 수수료 25만
B44: 현금사용/저축 | C44: =-E44*12 -> 1369680 | D44: 현금사용 | E44: =(-F37+C37-SUM(E38:E43)) -> -114140 | F44: 차보험/수리/세금 | G44: =-ROUND(1000000/12,-3)-ROUND(1200000/12,-3)-ROUND(600000/12,-3) -> -233000 | H44: 보험 : 5월 100만원(주차장사고로 인상?), 년수리비 120만원. 자동차세 년60만
...

Sheet 보증잔액 Table
B1: 년도별 지급금 & 보증잔액 (최대인출가능 : 156,865,000원)
B2: 주택가 : | C2: 685000000 | F2: 초기보증료 | G2: 6850000 | K2: 신탁방식(배우자 자동승계), 26/3/30일 신청 | M2: 매년4월말 기준 | P2: 수령액 복리합계 | R2: 누적수령액
B3: 해수 | C3: 연령 | D3: 년도 | E3: 월지급금 | F3: 년간 지급금 | G3: 누적지급금 | H3: 보증료 | I3: 대출이자 | J3: 보증잔액(상환대출금) | M3: 연금-보증잔액 | N3: 동일주택/평가금상향만 재가입불가 | P3: =SUM(P4:P39) -> 8.3674706e+08 | R3: 재산환산(월)
B4: 1 | C4: 65 | D4: 2026 | E4: 2203450 | F4: =E4*12 -> 26441400 | G4: =SUM(F$4:F4) -> 26441400 | H4: 7055362 | I4: 1057940 | J4: 34554702 | K4: =J4/J$39 -> 0.013216646 | M4: =ROUND(G4-J4,-6) -> -8000000 | N4: 주택가인상시 해지/매도 => 작은평 매수 / 재가입 | P4: =F4*1.02^(30-B4) -> 46955820 | R4: =-G4*0.04/12 -> -88138
B5: 2 | C5: 66 | D5: 2027 | E5: 2203450 | F5: =E5*12 -> 26441400 | G5: =SUM(F$4:F5) -> 52882800 | H5: 475724 | I5: 2450685 | J5: 63922511 | K5: =J5/J$39 -> 0.024449384 | M5: =ROUND(G5-J5,-6) -> -11000000 | N5: => 이사후 재평가로 연금액 상향조정도 좋은 방법임 | P5: =F5*1.02^(30-B5) -> 46035117 | R5: =-G5*0.04/12 -> -176276
B6: 3 | C6: 67 | D6: 2028 | E6: 2203450 | F6: =E6*12 -> 26441400 | G6: =SUM(F$4:F6) -> 79324200 | H6: 762312 | I6: 3927034 | J6: 95053257 | K6: =J6/J$39 -> 0.036356419 | M6: =ROUND(G6-J6,-6) -> -16000000 | N6: <<2027년말 7호선 개통>> | P6: =F6*1.02^(30-B6) -> 45132468 | R6: =-G6*0.04/12 -> -264414
B7: 4 | C7: 68 | D7: 2029 | E7: 2203450 | F7: =E7*12 -> 26441400 | G7: =SUM(F$4:F7) -> 105765600 | H7: 1066103 | I7: 5492007 | J7: 128052767 | K7: =J7/J$39 -> 0.048978228 | M7: =ROUND(G7-J7,-6) -> -22000000 | N7: 주택가 1억이상 인상시 해지/매도매입/재가입 고려 | P7: =F7*1.02^(30-B7) -> 44247518 | R7: =-G7*0.04/12 -> -352552
B8: 5 | C8: 69 | D8: 2030 | E8: 2203450 | F8: =E8*12 -> 26441400 | G8: =SUM(F$4:F8) -> 132207000 | H8: 1388138 | I8: 7150928 | J8: 163033233 | K8: =J8/J$39 -> 0.062357722 | M8: =ROUND(G8-J8,-6) -> -31000000 | N8: 최상의 시나리오 : 2028년 | P8: =F8*1.02^(30-B8) -> 43379919 | R8: =-G8*0.04/12 -> -440690
B9: 6 | C9: 70 | D9: 2031 | E9: 1542420 | F9: =E9*12 -> 18509040 | G9: =SUM(F$4:F9) -> 150716040 | H9: 1687940 | I9: 8695355 | J9: 191925568 | K9: =J9/J$39 -> 0.073408599 | M9: =ROUND(G9-J9,-6) -> -41000000 | N9: 1) 62평 : 8.5억으로 인상 | P9: =F9*1.02^(30-B9) -> 29770629 | R9: =-G9*0.04/12 -> -502386.8
B10: 7 | C10: 71 | D10: 2032 | E10: 1542420 | F10: =E10*12 -> 18509040 | G10: =SUM(F$4:F10) -> 169225080 | H10: 1969890 | I10: 10147803 | J10: 222552301 | K10: =J10/J$39 -> 0.085122857 | M10: =ROUND(G10-J10,-6) -> -53000000 | N10: 2) 33평 (or 43평) /저층 : 6.0억으로 인상 (실비용 6.5억) | P10: =F10*1.02^(30-B10) -> 29186892 | R10: =-G10*0.04/12 -> -564083.6
B11: 8 | C11: 72 | D11: 2033 | E11: 1542420 | F11: =E11*12 -> 18509040 | G11: =SUM(F$4:F11) -> 187734120 | H11: 2268764 | I11: 11687440 | J11: 255017545 | K11: =J11/J$39 -> 0.097540317 | M11: =ROUND(G11-J11,-6) -> -67000000 | N11: 3) 차액발생 : 2.0억 / 보증잔액제외 1.0억 | P11: =F11*1.02^(30-B11) -> 28614600 | R11: =-G11*0.04/12 -> -625780.4
B12: 9 | C12: 73 | D12: 2034 | E12: 1542420 | F12: =E12*12 -> 18509040 | G12: =SUM(F$4:F12) -> 206243160 | H12: 2585580 | I12: 13319502 | J12: 289431667 | K12: =J12/J$39 -> 0.11070319 | M12: =ROUND(G12-J12,-6) -> -83000000 | N12: : 기수령 연금액제외시, 2천만원 상환임 | P12: =F12*1.02^(30-B12) -> 28053529 | R12: =-G12*0.04/12 -> -687477.2
B13: 10 | C13: 74 | D13: 2035 | E13: 1542420 | F13: =E13*12 -> 18509040 | G13: =SUM(F$4:F13) -> 224752200 | H13: 2921416 | I13: 15049533 | J13: 325911656 | K13: =J13/J$39 -> 0.12465623 | M13: =ROUND(G13-J13,-6) -> -101000000 | N13: 4) 33평 (or 43평) 주택연금 가입 : 평가액 6.5억 | P13: =F13*1.02^(30-B13) -> 27503460 | R13: =-G13*0.04/12 -> -749174
B14: 11 | C14: 75 | D14: 2036 | E14: 1542420 | F14: =E14*12 -> 18509040 | G14: =SUM(F$4:F14) -> 243261240 | H14: 3277412 | I14: 16883420 | J14: 364581528 | K14: =J14/J$39 -> 0.13944687 | M14: =ROUND(G14-J14,-6) -> -121000000 | N14: : 초기증액형(5년) - 225만(5년) / 158만 | P14: =F14*1.02^(30-B14) -> 26964176 | R14: =-G14*0.04/12 -> -810870.8
B15: 12 | C15: 76 | D15: 2037 | E15: 1542420 | F15: =E15*12 -> 18509040 | G15: =SUM(F$4:F15) -> 261770280 | H15: 3654776 | I15: 18827392 | J15: 405572736 | K15: =J15/J$39 -> 0.15512538 | M15: =ROUND(G15-J15,-6) -> -144000000 | N15: ※ 연금액은 유지(5년은 인상) & 차액 1.0억 발생 | P15: =F15*1.02^(30-B15) -> 26435467 | R15: =-G15*0.04/12 -> -872567.6
... B18: 15 | C18: 79 | D18: 2040 | E18: 1542420 | F18: =E18*12 -> 18509040 | G18: =SUM(F$4:F18) -> 317297400 | H18: 4928311 | I18: 25387933 | J18: 543910217 | K18: =J18/J$39 -> 0.20803735 | M18: =ROUND(G18-J18,-6) -> -227000000 | N18: : 갑철 리빙케어 해지 8천만(?) 가능 | P18: =F18*1.02^(30-B18) -> 24910731 | R18: =-G18*0.04/12 -> -1057658
B19: 16 | C19: 80 | D19: 2041 | E19: 1542420 | F19: =E19*12 -> 18509040 | G19: =SUM(F$4:F19) -> 335806440 | H19: 5404777 | I19: 27842430 | J19: 595666464 | K19: =J19/J$39 -> 0.22783333 | M19: =ROUND(G19-J19,-6) -> -260000000 | P19: =F19*1.02^(30-B19) -> 24422285 | R19: =-G19*0.04/12 -> -1119354.8
B20: 17 | C20: 81 | D20: 2042 | E20: 1542420 | F20: =E20*12 -> 18509040 | G20: =SUM(F$4:F20) -> 354315480 | H20: 5909846 | I20: 30444269 | J20: 650529619 | K20: =J20/J$39 -> 0.24881765 | M20: =ROUND(G20-J20,-6) -> -296000000 | P20: =F20*1.02^(30-B20) -> 23943417 | R20: =-G20*0.04/12 -> -1181051.6
B21: 18 | C21: 82 | D21: 2043 | E21: 1542420 | F21: =E21*12 -> 18509040 | G21: =SUM(F$4:F21) -> 372824520 | H21: 6445237 | I21: 33202296 | J21: 708686192 | K21: =J21/J$39 -> 0.27106165 | M21: =ROUND(G21-J21,-6) -> -336000000 | P21: =F21*1.02^(30-B21) -> 23473938 | R21: =-G21*0.04/12 -> -1242748.4
B22: 19 | C22: 83 | D22: 2044 | E22: 1542420 | F22: =E22*12 -> 18509040 | G22: =SUM(F$4:F22) -> 391333560 | H22: 7012766 | I22: 36125886 | J22: 770333884 | K22: =J22/J$39 -> 0.29464095 | M22: =ROUND(G22-J22,-6) -> -379000000 | P22: =F22*1.02^(30-B22) -> 23013665 | R22: =-G22*0.04/12 -> -1304445.2
B23: 20 | C23: 84 | D23: 2045 | E23: 1542420 | F23: =E23*12 -> 18509040 | G23: =SUM(F$4:F23) -> 409842600 | H23: 7614360 | I23: 39224980 | J23: 835682264 | K23: =J23/J$39 -> 0.31963571 | M23: =ROUND(G23-J23,-6) -> -426000000 | P23: =F23*1.02^(30-B23) -> 22562416 | R23: =-G23*0.04/12 -> -1366142
B24: 21 | C24: 85 | D24: 2046 | E24: 1542420 | F24: =E24*12 -> 18509040 | G24: =SUM(F$4:F24) -> 428351640 | H24: 8252072 | I24: 42510109 | J24: 904953485 | K24: =J24/J$39 -> 0.34613089 | M24: =ROUND(G24-J24,-6) -> -477000000 | P24: =F24*1.02^(30-B24) -> 22120016 | R24: =-G24*0.04/12 -> -1427838.8
B25: 22 | C25: 86 | D25: 2047 | E25: 1542420 | F25: =E25*12 -> 18509040 | G25: =SUM(F$4:F25) -> 446860680 | H25: 8928064 | I25: 45992445 | J25: 978383034 | K25: =J25/J$39 -> 0.37421657 | M25: =ROUND(G25-J25,-6) -> -532000000 | P25: =F25*1.02^(30-B25) -> 21686290 | R25: =-G25*0.04/12 -> -1489535.6
B26: 23 | C26: 87 | D26: 2048 | E26: 1542420 | F26: =E26*12 -> 18509040 | G26: =SUM(F$4:F26) -> 465369720 | H26: 9644635 | I26: 49683821 | J26: 1056220530 | K26: =J26/J$39 -> 0.40398822 | M26: =ROUND(G26-J26,-6) -> -591000000 | P26: =F26*1.02^(30-B26) -> 21261069 | R26: =-G26*0.04/12 -> -1551232.4
B27: 24 | C27: 88 | D27: 2049 | E27: 1542420 | F27: =E27*12 -> 18509040 | G27: =SUM(F$4:F27) -> 483878760 | H27: 10404223 | I27: 53596792 | J27: 1138730585 | K27: =J27/J$39 -> 0.43554706 | M27: =ROUND(G27-J27,-6) -> -655000000 | P27: =F27*1.02^(30-B27) -> 20844185 | R27: =-G27*0.04/12 -> -1612929.2
B28: 25 | C28: 89 | D28: 2050 | E28: 1542420 | F28: =E28*12 -> 18509040 | G28: =SUM(F$4:F28) -> 502387800 | H28: 11209409 | I28: 57744656 | J28: 1226193690 | K28: =J28/J$39 -> 0.46900036 | M28: =ROUND(G28-J28,-6) -> -724000000 | P28: =F28*1.02^(30-B28) -> 20435476 | R28: =-G28*0.04/12 -> -1674626
B29: 26 | C29: 90 | D29: 2051 | E29: 1542420 | F29: =E29*12 -> 18509040 | G29: =SUM(F$4:F29) -> 520896840 | H29: 12062928 | I29: 62141516 | J29: 1318907174 | K29: =J29/J$39 -> 0.50446185 | M29: =ROUND(G29-J29,-6) -> -798000000 | P29: =F29*1.02^(30-B29) -> 20034780 | R29: =-G29*0.04/12 -> -1736322.8
B30: 27 | C30: 91 | D30: 2052 | E30: 1542420 | F30: =E30*12 -> 18509040 | G30: =SUM(F$4:F30) -> 539405880 | H30: 12967683 | I30: 68802318 | J30: 1417186215 | K30: =J30/J$39 -> 0.54205209 | M30: =ROUND(G30-J30,-6) -> -878000000 | P30: =F30*1.02^(30-B30) -> 19641941 | R30: =-G30*0.04/12 -> -1798019.6
... B34: 31 | C34: 95 | D34: 2056 | E34: 1542420 | F34: =E34*12 -> 18509040 | G34: =SUM(F$4:F34) -> 613442040 | H34: 17163426 | I34: 88416443 | J34: 1872948066 | K34: =J34/J$39 -> 0.71637404 | M34: =ROUND(G34-J34,-6) -> -1260000000 | P34: =F34*1.02^(30-B34) -> 18146118 | R34: =-G34*0.04/12 -> -2044806.8
B35: 32 | C35: 96 | D35: 2057 | E35: 1542420 | F35: =E35*12 -> 18509040 | G35: =SUM(F$4:F35) -> 631951080 | H35: 18374362 | I35: 94654518 | J35: 2004485986 | K35: =J35/J$39 -> 0.76668528 | M35: =ROUND(G35-J35,-6) -> -1373000000 | R35: =-G35*0.04/12 -> -2106503.6
B36: 33 | C36: 97 | D36: 2058 | E36: 1542420 | F36: =E36*12 -> 18509040 | G36: =SUM(F$4:F36) -> 650460120 | H36: 19657992 | I36: 101267066 | J36: 2143920084 | K36: =J36/J$39 -> 0.82001669 | M36: =ROUND(G36-J36,-6) -> -1493000000 | R36: =-G36*0.04/12 -> -2168200.4
B37: 34 | C37: 98 | D37: 2059 | E37: 1542420 | F37: =E37*12 -> 18509040 | G37: =SUM(F$4:F37) -> 668969160 | H37: 21018679 | I37: 108276559 | J37: 2291724362 | K37: =J37/J$39 -> 0.87654957 | L37: - 100세 이후 대비 | M37: =ROUND(G37-J37,-6) -> -1623000000 | R37: =-G37*0.04/12 -> -2229897.2
B38: 35 | C38: 99 | D38: 2060 | E38: 1542420 | F38: =E38*12 -> 18509040 | G38: =SUM(F$4:F38) -> 687478200 | H38: 22461047 | I38: 115706832 | J38: 2448401281 | K38: =J38/J$39 -> 0.9364761 | L38: - 설정비용은 많지않음 | M38: =ROUND(G38-J38,-6) -> -1761000000 | R38: =-G38*0.04/12 -> -2291594
B39: 36 | C39: 100 | D39: 2061 | E39: 1542420 | F39: =E39*12 -> 18509040 | G39: =SUM(F$4:F39) -> 705987240 | H39: 23989998 | I39: 123583139 | J39: 2614483458 | K39: =J39/J$39 -> 1 | M39: =ROUND(G39-J39,-6) -> -1908000000 | R39: =-G39*0.04/12 -> -2353290.8
B41: 기초연금 산정시는 대출금으로 계산됨
B42: 1) 자산은 주택가격으로, 연금수령액은 대출금으로 계산됨 (소득으로 인정되지 않음)
B43: 2) 기초생활보호대상자는 50%가 소득으로 인정됨
B45: 재산세 / 주택관리비 일체는 본인부담임
B46: 1) 재산세는 25% 감면됨
B48: 최대 인출한도금액 | E48: 156865000
...
